Workbook

Sheet Recommended_CEM_Base
A1: Recommended ERCOT CEM Base — Technology-Specific Sources (Real 2025$)
A2: Recommended hybrid base: ERCOT LTSA for gas / ICE / SMR / solar and 2h/6h storage; ATB Moderate Class 1 for wind; NLR 2025 Mid for 4-hour battery CAPEX; plus two separate diesel applications: backup generator and utility-scale peaker plant.
A3: Technology | B3: Economic life (yr) | C3: Real WACC | D3: 2030 CAPEX (2025$/kW) | E3: CRF | F3: 2030 annualized CAPEX (2025$/kW-yr) | G3: 2030 FOM (2025$/kW-yr) | H3: 2030 total fixed (2025$/kW-yr) | I3: VOM (2025$/MWh) | J3: Heat rate (Btu/kWh) | K3: 2035 CAPEX (2025$/kW) | L3: 2035 annualized CAPEX (2025$/kW-yr) | M3: 2035 FOM (2025$/kW-yr) | N3: 2035 total fixed (2025$/kW-yr) | O3: CAPEX source | P3: O&M source | Q3: Modeling note
A4: CC multi-shaft | B4: =Assumptions!B15 -> 30 | C4: =Assumptions!$B$5 -> 0.07 | D4: =ERCOT_LTSA_2026!B30 -> 1314.8599 | E4: =C4*(1+C4)^B4/((1+C4)^B4-1) -> 0.080586404 | F4: =D4*E4 -> 105.95983 | G4: =EIA_AEO2026_TRE!H6 -> 12.69 | H4: =F4+IF(G4="",0,G4) -> 118.64983 | I4: =EIA_AEO2026_TRE!I6 -> 3.57 | J4: =EIA_AEO2026_TRE!J6 -> 6226 | K4: =ERCOT_LTSA_2026!B35 -> 1254.1144 | L4: =K4*E4 -> 101.06457 | M4: =EIA_AEO2026_TRE!H6 -> 12.69 | N4: =L4+IF(M4="",0,M4) -> 113.75457 | O4: ERCOT 2026 LTSA | P4: EIA AEO2026; held constant in real 2025$ unless changed | Q4: Recommended base = ERCOT LTSA CAPEX; EIA TRE is a lower current regional anchor, not a 2030/2035 forecast.
A5: Advanced CT | B5: =Assumptions!B16 -> 30 | C5: =Assumptions!$B$5 -> 0.07 | D5: =ERCOT_LTSA_2026!C30 -> 1193.778 | E5: =C5*(1+C5)^B5/((1+C5)^B5-1) -> 0.080586404 | F5: =D5*E5 -> 96.202277 | G5: =EIA_AEO2026_TRE!H9 -> 7.18 | H5: =F5+IF(G5="",0,G5) -> 103.38228 | I5: =EIA_AEO2026_TRE!I9 -> 4.17 | J5: =EIA_AEO2026_TRE!J9 -> 9142 | K5: =ERCOT_LTSA_2026!C35 -> 1109.3161 | L5: =K5*E5 -> 89.395793 | M5: =EIA_AEO2026_TRE!H9 -> 7.18 | N5: =L5+IF(M5="",0,M5) -> 96.575793 | O5: ERCOT 2026 LTSA | P5: EIA AEO2026; held constant in real 2025$ unless changed | Q5: Recommended base = ERCOT LTSA CAPEX; EIA industrial-frame CT provides the current Texas regional anchor.
A6: ICE | B6: =Assumptions!B17 -> 30 | C6: =Assumptions!$B$5 -> 0.07 | D6: =ERCOT_LTSA_2026!D30 -> 2102.3408 | E6: =C6*(1+C6)^B6/((1+C6)^B6-1) -> 0.080586404 | F6: =D6*E6 -> 169.42009 | H6: =F6+IF(G6="",0,G6) -> 169.42009 | K6: =ERCOT_LTSA_2026!D35 -> 2036.8298 | L6: =K6*E6 -> 164.14079 | N6: =L6+IF(M6="",0,M6) -> 164.14079 | O6: ERCOT 2026 LTSA | P6: Not populated — add engine-specific O&M/performance source | Q6: ICE = reciprocating internal-combustion engine. Keep optional unless flexible engine capacity is explicitly represented; engine-specific O&M/heat rate still needed.
A7: SMR | B7: =Assumptions!B18 -> 60 | C7: =Assumptions!$B$5 -> 0.07 | D7: =ERCOT_LTSA_2026!E30 -> 8608.4759 | E7: =C7*(1+C7)^B7/((1+C7)^B7-1) -> 0.071229226 | F7: =D7*E7 -> 613.17507 | G7: =EIA_AEO2026_TRE!H11 -> 127.62 | H7: =F7+IF(G7="",0,G7) -> 740.79507 | I7: =EIA_AEO2026_TRE!I11 -> 3.32 | J7: =EIA_AEO2026_TRE!J11 -> 10445 | K7: =ERCOT_LTSA_2026!E35 -> 8133.6439 | L7: =K7*E7 -> 579.35315 | M7: =EIA_AEO2026_TRE!H11 -> 127.62 | N7: =L7+IF(M7="",0,M7) -> 706.97315 | O7: ERCOT 2026 LTSA | P7: EIA AEO2026; held constant in real 2025$ unless changed | Q7: Recommended central SMR CAPEX = ERCOT LTSA, but cost uncertainty is very large; retain ATB Advanced and Conservative cases as explicit low/high sensitivities.
A8: Wind | B8: =Assumptions!B19 -> 30 | C8: =Assumptions!$B$5 -> 0.07 | D8: =NLR_ATB_2024b!K15 -> 1548.8568 | E8: =C8*(1+C8)^B8/((1+C8)^B8-1) -> 0.080586404 | F8: =D8*E8 -> 124.8168 | G8: =NLR_ATB_2024b!M15 -> 32.1924 | H8: =F8+G8 -> 157.0092 | I8: =NLR_ATB_2024b!O15 -> 0 | K8: =NLR_ATB_2024b!L15 -> 1468.2638 | L8: =K8*E8 -> 118.3221 | M8: =NLR_ATB_2024b!N15 -> 31.089513 | N8: =L8+M8 -> 149.41161 | O8: NLR/NREL ATB 2024b Moderate — Wind Class 1 | P8: NLR/NREL ATB 2024b Moderate | Q8: Recommended base uses ATB Moderate Class 1 because ERCOT LTSA wind CAPEX is materially above ATB and recent ERCOT LBNL actuals; ERCOT LTSA is retained as a conservative/high benchmark.
A9: Solar | B9: =Assumptions!B20 -> 30 | C9: =Assumptions!$B$5 -> 0.07 | D9: =ERCOT_LTSA_2026!G30 -> 1171.3554 | E9: =C9*(1+C9)^B9/((1+C9)^B9-1) -> 0.080586404 | F9: =D9*E9 -> 94.395322 | G9: =EIA_AEO2026_TRE!H14 -> 23.6 | H9: =F9+IF(G9="",0,G9) -> 117.99532 | I9: =EIA_AEO2026_TRE!I14 -> 0 | K9: =ERCOT_LTSA_2026!G35 -> 1052.2012 | L9: =K9*E9 -> 84.793109 | M9: =EIA_AEO2026_TRE!H14 -> 23.6 | N9: =L9+IF(M9="",0,M9) -> 108.39311 | O9: ERCOT 2026 LTSA | P9: EIA AEO2026; held constant in real 2025$ unless changed | Q9: Recommended base = ERCOT LTSA solar CAPEX; ATB/EIA are relatively close and remain useful sensitivities/checks.
A10: BESS 2h | B10: =Assumptions!B21 -> 15 | C10: =Assumptions!$B$5 -> 0.07 | D10: =ERCOT_LTSA_2026!H30 -> 697.79061 | E10: =C10*(1+C10)^B10/((1+C10)^B10-1) -> 0.10979462 | F10: =D10*E10 -> 76.613658 | G10: =NLR_ATB_2024b!M24 -> 22.242684 | H10: =F10+IF(G10="",0,G10) -> 98.856342 | I10: =NLR_ATB_2024b!O24 -> 0 | K10: =ERCOT_LTSA_2026!H35 -> 645.15699 | L10: =K10*E10 -> 70.83477 | M10: =NLR_ATB_2024b!N24 -> 20.713591 | N10: =L10+IF(M10="",0,M10) -> 91.548361 | O10: ERCOT 2026 LTSA | P10: NLR/NREL ATB Moderate duration-specific O&M | Q10: 2-hour BESS remains an alternate-duration option; recommended CAPEX = ERCOT LTSA because the newer NLR 2025 projection is specifically used here for 4-hour storage.
A11: BESS 4h | B11: =Assumptions!B22 -> 15 | C11: =Assumptions!$B$5 -> 0.07 | D11: =NLR_BESS_2025!I11 -> 1145.365 | E11: =C11*(1+C11)^B11/((1+C11)^B11-1) -> 0.10979462 | F11: =D11*E11 -> 125.75492 | G11: =NLR_ATB_2024b!M27 -> 35.756699 | H11: =F11+G11 -> 161.51161 | I11: =NLR_ATB_2024b!O27 -> 0 | K11: =NLR_BESS_2025!I16 -> 997.57593 | L11: =K11*E11 -> 109.52847 | M11: =NLR_ATB_2024b!N27 -> 32.999473 | N11: =L11+M11 -> 142.52795 | O11: NLR 2025 Utility-Scale Battery Storage — Mid | P11: NLR/NREL ATB 2024b Moderate duration-specific O&M | Q11: Recommended 4-hour BESS CAPEX uses the newer NLR 2025 Mid trajectory; use NLR Low/High as the preferred battery cost sensitivities.
A12: BESS 6h | B12: =Assumptions!B23 -> 15 | C12: =Assumptions!$B$5 -> 0.07 | D12: =ERCOT_LTSA_2026!J30 -> 1705.0128 | E12: =C12*(1+C12)^B12/((1+C12)^B12-1) -> 0.10979462 | F12: =D12*E12 -> 187.20124 | G12: =NLR_ATB_2024b!M30 -> 49.270714 | H12: =F12+IF(G12="",0,G12) -> 236.47195 | I12: =NLR_ATB_2024b!O30 -> 0 | K12: =ERCOT_LTSA_2026!J35 -> 1576.6929 | L12: =K12*E12 -> 173.11241 | M12: =NLR_ATB_2024b!N30 -> 45.285354 | N12: =L12+IF(M12="",0,M12) -> 218.39776 | O12: ERCOT 2026 LTSA | P12: NLR/NREL ATB Moderate duration-specific O&M | Q12: 6-hour BESS remains an alternate-duration option; recommended CAPEX = ERCOT LTSA because the newer NLR 2025 projection is specifically used here for 4-hour storage.
A13: Diesel backup generator | B13: =Assumptions!B24 -> 20 | C13: =Assumptions!$B$5 -> 0.07 | D13: =Diesel_Review!B20 -> 800 | E13: =C13*(1+C13)^B13/((1+C13)^B13-1) -> 0.094392926 | F13: =D13*E13 -> 75.514341 | G13: =Diesel_Review!D20 -> 35 | H13: =F13+G13 -> 110.51434 | I13: =Diesel_Review!E20 -> 0 | J13: =Diesel_Review!F20*1000 -> 9500 | K13: =Diesel_Review!C20 -> 800 | L13: =K13*E13 -> 75.514341 | M13: =Diesel_Review!D20 -> 35 | N13: =L13+M13 -> 110.51434 | O13: Backup-generator synthesis (NREL / EDF / BofA / MIT) | P13: EDF 2024 non-fuel annual operating-cost benchmark | Q13: Standby/resilience generator. Recommended CAPEX is $800/kW in real 2025$ for both 2030 and 2035; do not use this row as the utility-scale peaker assumption.
A14: Diesel peaker plant | B14: 30 | C14: 0.07 | D14: 1373.9 | E14: 0.1 | F14: 110.7 | G14: 44.3 | H14: 155 | I14: 7.2 | J14: 9500 | K14: 1373.9 | L14: 110.7 | M14: 44.3 | N14: 155 | O14: EIA/S&L AEO2020 Texas 20-MW ICE plant | P14: EIA/S&L engine-plant O&M proxy | Q14: Utility-scale/grid-connected peaker. CAPEX = EIA Texas-Houston location-adjusted 20-MW internal-combustion-engine benchmark converted to 2025$. Kept separate from the $800/kW backup-generator case.
A15: Diesel peaker plant | B15: =Assumptions!B25 -> 30 | C15: =Assumptions!$B$5 -> 0.07 | D15: =Diesel_Review!B21 -> 1373.8713 | E15: =C15*(1+C15)^B15/((1+C15)^B15-1) -> 0.080586404 | F15: =D15*E15 -> 110.71535 | G15: =Diesel_Review!D21 -> 44.276182 | H15: =F15+G15 -> 154.99153 | I15: =Diesel_Review!E21 -> 7.1652866 | J15: =Diesel_Review!F21*1000 -> 9500 | K15: =Diesel_Review!C21 -> 1373.8713 | L15: =K15*E15 -> 110.71535 | M15: =Diesel_Review!D21 -> 44.276182 | N15: =L15+M15 -> 154.99153 | O15: EIA/S&L AEO2020 Texas 20-MW ICE plant | P15: EIA/S&L engine-plant O&M proxy | Q15: Utility-scale/grid-connected peaker. CAPEX = EIA Texas-Houston location-adjusted 20-MW internal-combustion-engine benchmark converted to 2025$. Kept separate from the $800/kW backup-generator case.
A17: Annualization method
A18: CRF = r(1+r)^n / [(1+r)^n - 1]. Annualized CAPEX = real-2025$ CAPEX × CRF. Total fixed = annualized CAPEX + FOM.
A19: The 7% real WACC and economic lives are editable assumptions on the Assumptions sheet; they are not source facts.
A20: For direct CEM import, the 2030 columns D/F/G/H/I/J and 2035 columns K/L/M/N are the main outputs.
A22: Recommended CAPEX Sensitivity Anchors — Real 2025$/kW
A23: Technology | B23: 2030 Low | C23: 2030 Base | D23: 2030 High | E23: 2035 Low | F23: 2035 Base | G23: 2035 High | H23: Guidance
A24: SMR | B24: =NLR_ATB_2024b!K11 -> 7058.9076 | C24: =D7 -> 8608.4759 | D24: =NLR_ATB_2024b!K13 -> 13950.214 | E24: =NLR_ATB_2024b!L11 -> 4222.7394 | F24: =K7 -> 8133.6439 | G24: =NLR_ATB_2024b!L13 -> 13259.61 | H24: Low = ATB Advanced; Base = ERCOT LTSA; High = ATB Conservative. Treat as a wide scenario range, not a tight confidence interval.
A25: Wind | B25: =NLR_ATB_2024b!K14 -> 1475.9427 | C25: =D8 -> 1548.8568 | D25: =CEM_BaseCase!D8 -> 2010.8567 | E25: =NLR_ATB_2024b!L14 -> 1384.776 | F25: =K8 -> 1468.2638 | G25: =CEM_BaseCase!K8 -> 1960.4085 | H25: Low = ATB Advanced Class 1; Base = ATB Moderate Class 1; High = ERCOT LTSA planning assumption. LBNL ERCOT actual cost remains an empirical calibration.
A26: BESS 4h | B26: =NLR_BESS_2025!H11 -> 849.7869 | C26: =D11 -> 1145.365 | D26: =NLR_BESS_2025!J11 -> 1453.2588 | E26: =NLR_BESS_2025!H16 -> 603.47186 | F26: =K11 -> 997.57593 | G26: =NLR_BESS_2025!J16 -> 1391.68 | H26: Low/Base/High = NLR 2025 Low/Mid/High trajectories; this is the preferred storage cost sensitivity family.
A27: Diesel backup generator | B27: =Diesel_Review!I20 -> 600 | C27: =Diesel_Review!J20 -> 800 | D27: =Diesel_Review!K20 -> 1000 | E27: =Diesel_Review!I20 -> 600 | F27: =Diesel_Review!J20 -> 800 | G27: =Diesel_Review!K20 -> 1000 | H27: Low/Base/High = $600/$800/$1,000 per kW in real 2025$ for a standby/resilience generator; held flat in real terms.
A28: Diesel peaker plant | B28: =Diesel_Review!I21 -> 1094.0493 | C28: =Diesel_Review!J21 -> 1373.8713 | D28: =Diesel_Review!K21 -> 1717.3391 | E28: =Diesel_Review!I21 -> 1094.0493 | F28: =Diesel_Review!J21 -> 1373.8713 | G28: =Diesel_Review!K21 -> 1717.3391 | H28: Low = EIA 2024 observed petroleum-liquids cost; Base = EIA Texas 20-MW ICE engineering benchmark; High = 25% stress case above base. Held flat in real terms.

Sheet Assumptions
A1: ERCOT CEM Technology-Cost Workbook — Conversion & Annualization Assumptions
A3: Assumption | B3: Value | C3: Unit | D3: Use | E3: Editable? | F3: Source / note
A4: ERCOT LTSA nominal inflation | B4: 0.022 | C4: %/yr | D4: Deflate ERCOT future nominal costs back to 2025$ | E4: Yes | F4: ERCOT 2026 LTSA
A5: Real discount rate / WACC | B5: 0.07 | C5: % | D5: Annualize CAPEX with a capital recovery factor | E5: Yes | F5: Modeling default — change to your CEM convention
A6: Base dollar year | B6: 2025 | C6: year | D6: Common comparison dollar year | E6: Yes | F6: User requested 2025$
A8: Dollar year | B8: CPI-U annual average | C8: 2025$/source-$ factor | D8: Source URL
A9: 2022 | B9: 292.655 | C9: =$B$12/B9 -> 1.1000769 | D9: https://www.bls.gov/regions/northeast/data/consumerpriceindex_us_table.htm
A10: 2023 | B10: 304.702 | C10: =$B$12/B10 -> 1.0565832 | D10: https://www.bls.gov/regions/northeast/data/consumerpriceindex_us_table.htm
A11: 2024 | B11: 313.689 | C11: =$B$12/B11 -> 1.0263127 | D11: https://www.bls.gov/regions/northeast/data/consumerpriceindex_us_table.htm
A12: 2025 | B12: 321.943 | C12: =$B$12/B12 -> 1 | D12: https://www.bls.gov/regions/northeast/data/consumerpriceindex_us_table.htm
A14: Technology | B14: Economic life (yr) | C14: Note
A15: CC multi-shaft | B15: 30 | C15: Editable CEM annualization assumption
A16: Advanced CT | B16: 30 | C16: Editable CEM annualization assumption
A17: ICE | B17: 30 | C17: Editable CEM annualization assumption
A18: SMR | B18: 60 | C18: Editable CEM annualization assumption
A19: Wind | B19: 30 | C19: Editable CEM annualization assumption
A20: Solar | B20: 30 | C20: Editable CEM annualization assumption
A21: BESS 2h | B21: 15 | C21: Editable CEM annualization assumption
A22: BESS 4h | B22: 15 | C22: Editable CEM annualization assumption
A23: BESS 6h | B23: 15 | C23: Editable CEM annualization assumption
A24: Diesel backup generator | B24: 20 | C24: NREL backup-generator useful life; editable CEM annualization assumption
A25: Diesel peaker plant | B25: 30 | C25: EIA utility-scale internal-combustion-engine operating life; editable CEM annualization assumption
A27: Conversion methodology
A28: 2022/2023/2024 source-dollar values are converted to 2025$ using annual-average U.S. CPI-U ratios.
A29: Conversion methodology
A30: 2022/2023/2024 source-dollar values are converted to 2025$ using annual-average U.S. CPI-U ratios.

Sheet README_Sources
A1: ERCOT Capacity-Expansion Technology Cost Assumptions — 2030 / 2035
A3: Source | B3: Role in workbook | C3: Geography | D3: Dollar basis | E3: Projection status | F3: Why useful for ERCOT | G3: URL
A4: ERCOT 2026 LTSA — Current Trends | B4: Primary base CAPEX | C4: ERCOT | D4: Nominal future $; converted to 2025$ | E4: 2027–2041 annual series | F4: ERCOT's own CEM/planning assumptions | G4: https://www.ercot.com/files/docs/2025/12/15/2026-LTSA-Update-Current-Trends-Capacity-Expansion-Results.pdf
A5: EIA AEO2026 Electricity Market Module | B5: Regional cost/O&M benchmark | C5: TRE = Texas | D5: 2025$ | E5: Initial/current new-build cost anchor | F5: Texas regional multipliers + updated gas turbine costs | G5: https://www.eia.gov/outlooks/aeo/assumptions/pdf/EMM_Assumptions.pdf
A6: NLR/NREL 2024b ATB v4 | B6: Technology-learning sensitivity | C6: U.S. / resource classes | D6: 2022$ | E6: 2030/2035 Advanced / Moderate / Conservative | F6: Transparent long-run technology learning cases | G6: https://data.openei.org/files/6006/2024_v4_Workbook_7-22-2026.xlsx
A7: NLR Utility-Scale Battery Storage 2025 Update | B7: Battery-specific sensitivity | C7: U.S. | D7: 2024$ | E7: Annual future projections | F7: More current storage learning than frozen 2024 ATB | G7: https://www.nlr.gov/docs/fy25osti/93281.pdf
A8: Berkeley Lab Land-Based Wind Market Report 2024 | B8: Empirical calibration | C8: ERCOT | D8: 2023$ | E8: Historical actual 2022–2023 projects | F8: Direct ERCOT observed project-cost benchmark | G8: https://emp.lbl.gov/sites/default/files/2024-08/Land-Based%20Wind%20Market%20Report_2024%20Edition.pdf
A9: Berkeley Lab Utility-Scale Solar 2025 | B9: Empirical calibration | C9: U.S. | D9: 2024$ | E9: Historical actual 2024 projects | F9: Observed utility-scale PV benchmark; not ERCOT-specific | G9: https://emp.lbl.gov/publications/us-utility-scale-solar-2025-data
A10: BLS CPI-U | B10: Dollar-year conversion | C10: U.S. | D10: Index | E10: Historical | F10: Transparent conversion to 2025 dollars | G10: https://www.bls.gov/regions/northeast/data/consumerpriceindex_us_table.htm
A11: Lazard LCOE+ v18 | B11: Underlying/secondary benchmark | C11: U.S. | D11: Varies | E11: Market benchmark | F11: Cited by ERCOT LTSA as an input source; not separately harmonized | G11: https://www.lazard.com/research-insights/levelized-cost-of-energyplus/
A12: Diesel technology review | B12: Backup-generator + utility-scale peaker benchmark | C12: U.S.; Texas-specific engineering benchmark for peaker | D12: Mixed source years normalized to 2025$ | E12: Mature technology; flat-real-cost base assumption | F12: Separates standby backup generator from a grid-connected liquid-fuel peaker; detailed reconciliation is in Diesel_Review. | G12: https://www.eia.gov/analysis/studies/powerplants/capitalcost/pdf/capital_cost_AEO2020.pdf
A13: Recommended interpretation
A14: Base case | B14: Use the technology-specific hybrid in Recommended_CEM_Base: ERCOT LTSA for gas/ICE/SMR/solar and 2h/6h BESS; ATB Moderate Class 1 for wind; NLR 2025 Mid for 4h BESS; $800/kW backup diesel for standby use; and the EIA Texas utility-scale ICE benchmark for diesel peaker.
A15: Cross-check | B15: Use EIA TRE/Texas as a current regional anchor; do not relabel it as an explicit 2030/2035 forecast.
A16: Learning sensitivities | B16: Wind: ATB Advanced / Moderate with ERCOT LTSA as conservative planning benchmark. 4h BESS: NLR 2025 Low/Mid/High. SMR: ATB Advanced / ERCOT / ATB Conservative.
A17: Empirical calibration | B17: Use LBNL actual wind/solar costs as a reality check, not as forward projections.
A18: Annualization | B18: Recommended_CEM_Base applies the editable real WACC/life and then adds FOM; HOPE_CostProfiles converts the recommended fixed cost to $/MW-yr.
A19: Workbook navigation | B19: Recommended_CEM_Base = preferred hybrid inputs; CEM_BaseCase = all-ERCOT-LTSA benchmark; HOPE_CostProfiles = HOPE-formatted recommended costs.
A20: HOPE model-input format references (from current GitHub project)
A21: HOPE candidate cost profile | B21: candidate_resource_costs_2035.csv | C21: Current HOPE project format | D21: Stores CAPEX/FOM/FCR plus final $/MW-yr and $/MWh | E21: Used by the case builder | F21: HOPE_CostProfiles follows this schema in columns A:U | G21: https://github.com/swang22/PJM_DC_health_study_project/blob/main/scenario_assumptions/candidate_resource_costs_2035.csv
A22: HOPE generation candidates | B22: gendata_candidate.csv | C22: Current HOPE project format | D22: Direct model input | E22: Project/zone/build limit + fixed/variable cost + reliability/emissions | F22: HOPE_GenCandidate follows the exact model columns in A:Y | G22: https://github.com/swang22/PJM_DC_health_study_project/blob/main/ModelCases/PJM_ICARUS21_GTEP_2035_Base_case/Data_PJM_ICARUS21_GTEP_2035_Base/gendata_candidate.csv
A23: HOPE storage candidates | B23: storagedata_candidate.csv | C23: Current HOPE project format | D23: Direct model input | E23: Energy/power capacity + efficiency + fixed/variable cost + CC | F23: HOPE_StorageCandidate follows the exact model columns in A:V | G23: https://github.com/swang22/PJM_DC_health_study_project/blob/main/ModelCases/PJM_ICARUS21_GTEP_2035_Base_case/Data_PJM_ICARUS21_GTEP_2035_Base/storagedata_candidate.csv

Sheet ERCOT_LTSA_2026
A1: ERCOT 2026 LTSA — New Unit Capital Costs
A2: Source: | B2: https://www.ercot.com/files/docs/2025/12/15/2026-LTSA-Update-Current-Trends-Capacity-Expansion-Results.pdf
A4: Raw source values — nominal $/kW
A5: Year | B5: CC multi-shaft | C5: Advanced CT | D5: ICE | E5: SMR | F5: Wind | G5: Solar | H5: BESS 2h | I5: BESS 4h | J5: BESS 6h
B6: nominal $/kW | C6: nominal $/kW | D6: nominal $/kW | E6: nominal $/kW | F6: nominal $/kW | G6: nominal $/kW | H6: nominal $/kW | I6: nominal $/kW | J6: nominal $/kW
A7: 2027 | B7: 1436 | C7: 1325 | D7: 2236 | E7: 9439 | F7: 2165 | G7: 1308 | H7: 782 | I7: 1347 | J7: 1912
A8: 2028 | B8: 1439 | C8: 1319 | D8: 2272 | E8: 9450 | F8: 2180 | G8: 1289 | H8: 770 | I8: 1326 | J8: 1882
A9: 2029 | B9: 1449 | C9: 1321 | D9: 2308 | E9: 9509 | F9: 2207 | G9: 1296 | H9: 772 | I9: 1329 | J9: 1887
A10: 2030 | B10: 1466 | C10: 1331 | D10: 2344 | E10: 9598 | F10: 2242 | G10: 1306 | H10: 778 | I10: 1339 | J10: 1901
A11: 2031 | B11: 1487 | C11: 1344 | D11: 2379 | E11: 9716 | F11: 2284 | G11: 1307 | H11: 786 | I11: 1352 | J11: 1920
A12: 2032 | B12: 1508 | C12: 1357 | D12: 2417 | E12: 9831 | F12: 2325 | G12: 1311 | H12: 789 | I12: 1359 | J12: 1929
A13: 2033 | B13: 1529 | C13: 1369 | D13: 2456 | E13: 9938 | F13: 2365 | G13: 1313 | H13: 795 | I13: 1368 | J13: 1942
A14: 2034 | B14: 1540 | C14: 1364 | D14: 2494 | E14: 10033 | F14: 2403 | G14: 1312 | H14: 798 | I14: 1374 | J14: 1950
A15: 2035 | B15: 1559 | C15: 1379 | D15: 2532 | E15: 10111 | F15: 2437 | G15: 1308 | H15: 802 | I15: 1381 | J15: 1960
A16: 2036 | B16: 1581 | C16: 1395 | D16: 2568 | E16: 10201 | F16: 2475 | G16: 1308 | H16: 806 | I16: 1387 | J16: 1969
A17: 2037 | B17: 1606 | C17: 1415 | D17: 2606 | E17: 10311 | F17: 2518 | G17: 1317 | H17: 810 | I17: 1394 | J17: 1979
A18: 2038 | B18: 1633 | C18: 1437 | D18: 2645 | E18: 10425 | F18: 2563 | G18: 1328 | H18: 814 | I18: 1402 | J18: 1990
... A21: 2041 | B21: 1714 | C21: 1502 | D21: 2766 | E21: 10760 | F21: 2700 | G21: 1376 | H21: 829 | I21: 1428 | J21: 2027
A24: Converted values — real 2025$/kW
A25: Year | B25: CC multi-shaft | C25: Advanced CT | D25: ICE | E25: SMR | F25: Wind | G25: Solar | H25: BESS 2h | I25: BESS 4h | J25: BESS 6h
B26: 2025$/kW | C26: 2025$/kW | D26: 2025$/kW | E26: 2025$/kW | F26: 2025$/kW | G26: 2025$/kW | H26: 2025$/kW | I26: 2025$/kW | J26: 2025$/kW
A27: =A7 -> 2027 | B27: =B7/(1+Assumptions!$B$4)^(A27-Assumptions!$B$6) -> 1374.8415 | C27: =C7/(1+Assumptions!$B$4)^(A27-Assumptions!$B$6) -> 1268.569 | D27: =D7/(1+Assumptions!$B$4)^(A27-Assumptions!$B$6) -> 2140.77 | E27: =E7/(1+Assumptions!$B$4)^(A27-Assumptions!$B$6) -> 9036.9982 | F27: =F7/(1+Assumptions!$B$4)^(A27-Assumptions!$B$6) -> 2072.7938 | G27: =G7/(1+Assumptions!$B$4)^(A27-Assumptions!$B$6) -> 1252.293 | H27: =H7/(1+Assumptions!$B$4)^(A27-Assumptions!$B$6) -> 748.69505 | I27: =I7/(1+Assumptions!$B$4)^(A27-Assumptions!$B$6) -> 1289.632 | J27: =J7/(1+Assumptions!$B$4)^(A27-Assumptions!$B$6) -> 1830.569
A28: =A8 -> 2028 | B28: =B8/(1+Assumptions!$B$4)^(A28-Assumptions!$B$6) -> 1348.0565 | C28: =C8/(1+Assumptions!$B$4)^(A28-Assumptions!$B$6) -> 1235.6404 | D28: =D8/(1+Assumptions!$B$4)^(A28-Assumptions!$B$6) -> 2128.4117 | E28: =E8/(1+Assumptions!$B$4)^(A28-Assumptions!$B$6) -> 8852.7688 | F28: =F8/(1+Assumptions!$B$4)^(A28-Assumptions!$B$6) -> 2042.226 | G28: =G8/(1+Assumptions!$B$4)^(A28-Assumptions!$B$6) -> 1207.5364 | H28: =H8/(1+Assumptions!$B$4)^(A28-Assumptions!$B$6) -> 721.33672 | I28: =I8/(1+Assumptions!$B$4)^(A28-Assumptions!$B$6) -> 1242.198 | J28: =J8/(1+Assumptions!$B$4)^(A28-Assumptions!$B$6) -> 1763.0593
A29: =A9 -> 2029 | B29: =B9/(1+Assumptions!$B$4)^(A29-Assumptions!$B$6) -> 1328.2041 | C29: =C9/(1+Assumptions!$B$4)^(A29-Assumptions!$B$6) -> 1210.8748 | D29: =D9/(1+Assumptions!$B$4)^(A29-Assumptions!$B$6) -> 2115.5935 | E29: =E9/(1+Assumptions!$B$4)^(A29-Assumptions!$B$6) -> 8716.2818 | F29: =F9/(1+Assumptions!$B$4)^(A29-Assumptions!$B$6) -> 2023.0134 | G29: =G9/(1+Assumptions!$B$4)^(A29-Assumptions!$B$6) -> 1187.9589 | H29: =H9/(1+Assumptions!$B$4)^(A29-Assumptions!$B$6) -> 707.64219 | I29: =I9/(1+Assumptions!$B$4)^(A29-Assumptions!$B$6) -> 1218.2079 | J29: =J9/(1+Assumptions!$B$4)^(A29-Assumptions!$B$6) -> 1729.6902
A30: =A10 -> 2030 | B30: =B10/(1+Assumptions!$B$4)^(A30-Assumptions!$B$6) -> 1314.8599 | C30: =C10/(1+Assumptions!$B$4)^(A30-Assumptions!$B$6) -> 1193.778 | D30: =D10/(1+Assumptions!$B$4)^(A30-Assumptions!$B$6) -> 2102.3408 | E30: =E10/(1+Assumptions!$B$4)^(A30-Assumptions!$B$6) -> 8608.4759 | F30: =F10/(1+Assumptions!$B$4)^(A30-Assumptions!$B$6) -> 2010.8567 | G30: =G10/(1+Assumptions!$B$4)^(A30-Assumptions!$B$6) -> 1171.3554 | H30: =H10/(1+Assumptions!$B$4)^(A30-Assumptions!$B$6) -> 697.79061 | I30: =I10/(1+Assumptions!$B$4)^(A30-Assumptions!$B$6) -> 1200.9532 | J30: =J10/(1+Assumptions!$B$4)^(A30-Assumptions!$B$6) -> 1705.0128
A31: =A11 -> 2031 | B31: =B11/(1+Assumptions!$B$4)^(A31-Assumptions!$B$6) -> 1304.9852 | C31: =C11/(1+Assumptions!$B$4)^(A31-Assumptions!$B$6) -> 1179.489 | D31: =D11/(1+Assumptions!$B$4)^(A31-Assumptions!$B$6) -> 2087.8008 | E31: =E11/(1+Assumptions!$B$4)^(A31-Assumptions!$B$6) -> 8526.7225 | F31: =F11/(1+Assumptions!$B$4)^(A31-Assumptions!$B$6) -> 2004.4292 | G31: =G11/(1+Assumptions!$B$4)^(A31-Assumptions!$B$6) -> 1147.0179 | H31: =H11/(1+Assumptions!$B$4)^(A31-Assumptions!$B$6) -> 689.79044 | I31: =I11/(1+Assumptions!$B$4)^(A31-Assumptions!$B$6) -> 1186.5098 | J31: =J11/(1+Assumptions!$B$4)^(A31-Assumptions!$B$6) -> 1684.9843
A32: =A12 -> 2032 | B32: =B12/(1+Assumptions!$B$4)^(A32-Assumptions!$B$6) -> 1294.9264 | C32: =C12/(1+Assumptions!$B$4)^(A32-Assumptions!$B$6) -> 1165.262 | D32: =D12/(1+Assumptions!$B$4)^(A32-Assumptions!$B$6) -> 2075.4887 | E32: =E12/(1+Assumptions!$B$4)^(A32-Assumptions!$B$6) -> 8441.9238 | F32: =F12/(1+Assumptions!$B$4)^(A32-Assumptions!$B$6) -> 1996.4879 | G32: =G12/(1+Assumptions!$B$4)^(A32-Assumptions!$B$6) -> 1125.7616 | H32: =H12/(1+Assumptions!$B$4)^(A32-Assumptions!$B$6) -> 677.51784 | I32: =I12/(1+Assumptions!$B$4)^(A32-Assumptions!$B$6) -> 1166.9794 | J32: =J12/(1+Assumptions!$B$4)^(A32-Assumptions!$B$6) -> 1656.4409
A33: =A13 -> 2033 | B33: =B13/(1+Assumptions!$B$4)^(A33-Assumptions!$B$6) -> 1284.6958 | C33: =C13/(1+Assumptions!$B$4)^(A33-Assumptions!$B$6) -> 1150.2607 | D33: =D13/(1+Assumptions!$B$4)^(A33-Assumptions!$B$6) -> 2063.5795 | E33: =E13/(1+Assumptions!$B$4)^(A33-Assumptions!$B$6) -> 8350.1029 | F33: =F13/(1+Assumptions!$B$4)^(A33-Assumptions!$B$6) -> 1987.1195 | G33: =G13/(1+Assumptions!$B$4)^(A33-Assumptions!$B$6) -> 1103.2084 | H33: =H13/(1+Assumptions!$B$4)^(A33-Assumptions!$B$6) -> 667.97462 | I33: =I13/(1+Assumptions!$B$4)^(A33-Assumptions!$B$6) -> 1149.4205 | J33: =J13/(1+Assumptions!$B$4)^(A33-Assumptions!$B$6) -> 1631.7066
A34: =A14 -> 2034 | B34: =B14/(1+Assumptions!$B$4)^(A34-Assumptions!$B$6) -> 1266.0844 | C34: =C14/(1+Assumptions!$B$4)^(A34-Assumptions!$B$6) -> 1121.389 | D34: =D14/(1+Assumptions!$B$4)^(A34-Assumptions!$B$6) -> 2050.399 | E34: =E14/(1+Assumptions!$B$4)^(A34-Assumptions!$B$6) -> 8248.4577 | F34: =F14/(1+Assumptions!$B$4)^(A34-Assumptions!$B$6) -> 1975.5849 | G34: =G14/(1+Assumptions!$B$4)^(A34-Assumptions!$B$6) -> 1078.6381 | H34: =H14/(1+Assumptions!$B$4)^(A34-Assumptions!$B$6) -> 656.06192 | I34: =I14/(1+Assumptions!$B$4)^(A34-Assumptions!$B$6) -> 1129.6104 | J34: =J14/(1+Assumptions!$B$4)^(A34-Assumptions!$B$6) -> 1603.1588
A35: =A15 -> 2035 | B35: =B15/(1+Assumptions!$B$4)^(A35-Assumptions!$B$6) -> 1254.1144 | C35: =C15/(1+Assumptions!$B$4)^(A35-Assumptions!$B$6) -> 1109.3161 | D35: =D15/(1+Assumptions!$B$4)^(A35-Assumptions!$B$6) -> 2036.8298 | E35: =E15/(1+Assumptions!$B$4)^(A35-Assumptions!$B$6) -> 8133.6439 | F35: =F15/(1+Assumptions!$B$4)^(A35-Assumptions!$B$6) -> 1960.4085 | G35: =G15/(1+Assumptions!$B$4)^(A35-Assumptions!$B$6) -> 1052.2012 | H35: =H15/(1+Assumptions!$B$4)^(A35-Assumptions!$B$6) -> 645.15699 | I35: =I15/(1+Assumptions!$B$4)^(A35-Assumptions!$B$6) -> 1110.9249 | J35: =J15/(1+Assumptions!$B$4)^(A35-Assumptions!$B$6) -> 1576.6929
A36: =A16 -> 2036 | B36: =B16/(1+Assumptions!$B$4)^(A36-Assumptions!$B$6) -> 1244.4344 | C36: =C16/(1+Assumptions!$B$4)^(A36-Assumptions!$B$6) -> 1098.0304 | D36: =D16/(1+Assumptions!$B$4)^(A36-Assumptions!$B$6) -> 2021.3204 | E36: =E16/(1+Assumptions!$B$4)^(A36-Assumptions!$B$6) -> 8029.3963 | F36: =F16/(1+Assumptions!$B$4)^(A36-Assumptions!$B$6) -> 1948.1184 | G36: =G16/(1+Assumptions!$B$4)^(A36-Assumptions!$B$6) -> 1029.5511 | H36: =H16/(1+Assumptions!$B$4)^(A36-Assumptions!$B$6) -> 634.41755 | I36: =I16/(1+Assumptions!$B$4)^(A36-Assumptions!$B$6) -> 1091.7334 | J36: =J16/(1+Assumptions!$B$4)^(A36-Assumptions!$B$6) -> 1549.8364
A37: =A17 -> 2037 | B37: =B17/(1+Assumptions!$B$4)^(A37-Assumptions!$B$6) -> 1236.9006 | C37: =C17/(1+Assumptions!$B$4)^(A37-Assumptions!$B$6) -> 1089.7972 | D37: =D17/(1+Assumptions!$B$4)^(A37-Assumptions!$B$6) -> 2007.0753 | E37: =E17/(1+Assumptions!$B$4)^(A37-Assumptions!$B$6) -> 7941.2714 | F37: =F17/(1+Assumptions!$B$4)^(A37-Assumptions!$B$6) -> 1939.2999 | G37: =G17/(1+Assumptions!$B$4)^(A37-Assumptions!$B$6) -> 1014.3201 | H37: =H17/(1+Assumptions!$B$4)^(A37-Assumptions!$B$6) -> 623.84151 | I37: =I17/(1+Assumptions!$B$4)^(A37-Assumptions!$B$6) -> 1073.6235 | J37: =J17/(1+Assumptions!$B$4)^(A37-Assumptions!$B$6) -> 1524.1757
A38: =A18 -> 2038 | B38: =B18/(1+Assumptions!$B$4)^(A38-Assumptions!$B$6) -> 1230.6216 | C38: =C18/(1+Assumptions!$B$4)^(A38-Assumptions!$B$6) -> 1082.9169 | D38: =D18/(1+Assumptions!$B$4)^(A38-Assumptions!$B$6) -> 1993.2604 | E38: =E18/(1+Assumptions!$B$4)^(A38-Assumptions!$B$6) -> 7856.2341 | F38: =F18/(1+Assumptions!$B$4)^(A38-Assumptions!$B$6) -> 1931.4655 | G38: =G18/(1+Assumptions!$B$4)^(A38-Assumptions!$B$6) -> 1000.775 | H38: =H18/(1+Assumptions!$B$4)^(A38-Assumptions!$B$6) -> 613.42682 | I38: =I18/(1+Assumptions!$B$4)^(A38-Assumptions!$B$6) -> 1056.541 | J38: =J18/(1+Assumptions!$B$4)^(A38-Assumptions!$B$6) -> 1499.6552
... A41: =A21 -> 2041 | B41: =B21/(1+Assumptions!$B$4)^(A41-Assumptions!$B$6) -> 1210.031 | C41: =C21/(1+Assumptions!$B$4)^(A41-Assumptions!$B$6) -> 1060.3655 | D41: =D21/(1+Assumptions!$B$4)^(A41-Assumptions!$B$6) -> 1952.7104 | E41: =E21/(1+Assumptions!$B$4)^(A41-Assumptions!$B$6) -> 7596.2271 | F41: =F21/(1+Assumptions!$B$4)^(A41-Assumptions!$B$6) -> 1906.1165 | G41: =G21/(1+Assumptions!$B$4)^(A41-Assumptions!$B$6) -> 971.41342 | H41: =H21/(1+Assumptions!$B$4)^(A41-Assumptions!$B$6) -> 585.24835 | I41: =I21/(1+Assumptions!$B$4)^(A41-Assumptions!$B$6) -> 1008.1238 | J41: =J21/(1+Assumptions!$B$4)^(A41-Assumptions!$B$6) -> 1430.9993
A43: Notes
A44: ERCOT's source table is nominal $/kW; the 2025$ table uses ERCOT's 2.2% annual inflation assumption.
A45: These are the preferred ERCOT-specific base-case new-build CAPEX assumptions in this workbook.
A46: FOM/VOM are not supplied in this LTSA capital-cost table; see EIA and ATB sheets.

Sheet EIA_AEO2026_TRE
A1: EIA AEO2026 — New-Build Cost & Performance Assumptions (TRE / Texas)
A2: Source: | B2: https://www.eia.gov/outlooks/aeo/assumptions/pdf/EMM_Assumptions.pdf
A4: Technology | B4: First available year | C4: Size (MW) | D4: Lead time (yr) | E4: Base overnight cost (2025$/kW) | F4: Total overnight cost (2025$/kW) | G4: TRE regional overnight cost (2025$/kW) | H4: FOM (2025$/kW-yr) | I4: VOM (2025$/MWh) | J4: Heat rate / EIA convention (Btu/kWh) | K4: Notes | L4: Source URL
A5: CC single-shaft | B5: 2028 | C5: 627 | D5: 3 | E5: 1086 | F5: 1086 | G5: 980 | H5: 16.23 | I5: 3.49 | J5: 6226 | K5: TRE = Texas Reliability Entity | L5: https://www.eia.gov/outlooks/aeo/assumptions/pdf/EMM_Assumptions.pdf
A6: CC multi-shaft | B6: 2028 | C6: 1227 | D6: 3 | E6: 1032 | F6: 1032 | G6: 930 | H6: 12.69 | I6: 3.57 | J6: 6226 | K6: Preferred EIA comparator for ERCOT CC | L6: https://www.eia.gov/outlooks/aeo/assumptions/pdf/EMM_Assumptions.pdf
A7: CC with 95% CCS | B7: 2029 | C7: 543 | D7: 4 | E7: 2567 | F7: 2824 | G7: 2504 | H7: 25.93 | I7: 5.29 | J7: 7239 | L7: https://www.eia.gov/outlooks/aeo/assumptions/pdf/EMM_Assumptions.pdf
A8: CT aeroderivative | B8: 2027 | C8: 211 | D8: 2 | E8: 2275 | F8: 2275 | G8: 2058 | H8: 9.99 | I8: 5.97 | J8: 9447 | L8: https://www.eia.gov/outlooks/aeo/assumptions/pdf/EMM_Assumptions.pdf
A9: CT industrial frame | B9: 2027 | C9: 419 | D9: 2 | E9: 1158 | F9: 1158 | G9: 1033 | H9: 7.18 | I9: 4.17 | J9: 9142 | K9: Preferred EIA comparator for ERCOT CT | L9: https://www.eia.gov/outlooks/aeo/assumptions/pdf/EMM_Assumptions.pdf
A10: Nuclear - large LWR | B10: 2031 | C10: 2156 | D10: 6 | E10: 7862 | F10: 8255 | G10: 7866 | H10: 163.4 | I10: 2.62 | J10: 10445 | L10: https://www.eia.gov/outlooks/aeo/assumptions/pdf/EMM_Assumptions.pdf
A11: Nuclear - SMR | B11: 2031 | C11: 480 | D11: 6 | E11: 8937 | F11: 9831 | G11: 9366 | H11: 127.62 | I11: 3.32 | J11: 10445 | L11: https://www.eia.gov/outlooks/aeo/assumptions/pdf/EMM_Assumptions.pdf
A12: Battery storage - 4h Li-ion | B12: 2026 | C12: 150 | D12: 1 | E12: 1521 | F12: 1521 | G12: 1500 | H12: 41.84 | I12: 0 | K12: EIA defines battery storage as four-hour Li-ion | L12: https://www.eia.gov/outlooks/aeo/assumptions/pdf/EMM_Assumptions.pdf
A13: Wind - onshore | B13: 2028 | C13: 200 | D13: 3 | E13: 1712 | F13: 1712 | G13: 1562 | H13: 34.57 | I13: 0 | J13: 3412 | K13: 3,412 is EIA primary-energy heat-content convention, not a thermal efficiency | L13: https://www.eia.gov/outlooks/aeo/assumptions/pdf/EMM_Assumptions.pdf
A14: Solar PV - tracking | B14: 2027 | C14: 150 | D14: 2 | E14: 1484 | F14: 1484 | G14: 1342 | H14: 23.6 | I14: 0 | J14: 3412 | K14: Costs/capacity expressed on an AC basis | L14: https://www.eia.gov/outlooks/aeo/assumptions/pdf/EMM_Assumptions.pdf
A15: Solar PV + storage | B15: 2027 | C15: 150 | D15: 2 | E15: 1903 | F15: 1903 | G15: 1840 | H15: 40 | I15: 0 | J15: 3412 | K15: 150 MW PV + 50 MW four-hour battery | L15: https://www.eia.gov/outlooks/aeo/assumptions/pdf/EMM_Assumptions.pdf
A18: Interpretation
A19: TRE is EIA region 1, Texas Reliability Entity. Use the TRE cost as a regional cross-check, not as an explicit EIA 2030/2035 point.
A20: AEO2026 updated CC/CT inputs for recent turbine, materials, and labor tightness and applies regional/locality adjustments.
A21: EIA explicitly represents battery storage as a four-hour lithium-ion battery.

Sheet NLR_ATB_2024b
A1: NLR/NREL 2024b ATB v4 — 2030 / 2035 Cost Scenarios
A2: Source workbook: | B2: https://data.openei.org/files/6006/2024_v4_Workbook_7-22-2026.xlsx
A4: Technology | B4: ATB detail | C4: Scenario | D4: CRP years | E4: CAPEX 2030 (2022$/kW) | F4: CAPEX 2035 (2022$/kW) | G4: FOM 2030 (2022$/kW-yr) | H4: FOM 2035 (2022$/kW-yr) | I4: VOM 2030 (2022$/MWh) | J4: VOM 2035 (2022$/MWh) | K4: CAPEX 2030 (2025$/kW) | L4: CAPEX 2035 (2025$/kW) | M4: FOM 2030 (2025$/kW-yr) | N4: FOM 2035 (2025$/kW-yr) | O4: VOM 2030 (2025$/MWh) | P4: VOM 2035 (2025$/MWh) | Q4: Source URL
A5: CC F-frame | B5: NG 2-on-1 Combined Cycle (F-Frame) | C5: Advanced | D5: 30 | E5: 1381.1314 | F5: 1307.2497 | G5: 30.7 | H5: 28.3 | I5: 2 | J5: 1.89 | K5: =E5*Assumptions!$C$9 -> 1519.3508 | L5: =F5*Assumptions!$C$9 -> 1438.0752 | M5: =G5*Assumptions!$C$9 -> 33.77236 | N5: =H5*Assumptions!$C$9 -> 31.132176 | O5: =I5*Assumptions!$C$9 -> 2.2001538 | P5: =J5*Assumptions!$C$9 -> 2.0791453 | Q5: https://data.openei.org/files/6006/2024_v4_Workbook_7-22-2026.xlsx
A6: CC F-frame | B6: NG 2-on-1 Combined Cycle (F-Frame) | C6: Moderate | D6: 30 | E6: 1403.3071 | F6: 1343.3548 | G6: 31.8 | H6: 30.1 | I6: 2.04 | J6: 1.96 | K6: =E6*Assumptions!$C$9 -> 1543.7457 | L6: =F6*Assumptions!$C$9 -> 1477.7936 | M6: =G6*Assumptions!$C$9 -> 34.982445 | N6: =H6*Assumptions!$C$9 -> 33.112314 | O6: =I6*Assumptions!$C$9 -> 2.2441568 | P6: =J6*Assumptions!$C$9 -> 2.1561507 | Q6: https://data.openei.org/files/6006/2024_v4_Workbook_7-22-2026.xlsx
A7: CC F-frame | B7: NG 2-on-1 Combined Cycle (F-Frame) | C7: Conservative | D7: 30 | E7: 1425.4828 | F7: 1379.3485 | G7: 32.8 | H7: 31.8 | I7: 2.08 | J7: 2.03 | K7: =E7*Assumptions!$C$9 -> 1568.1406 | L7: =F7*Assumptions!$C$9 -> 1517.3894 | M7: =G7*Assumptions!$C$9 -> 36.082522 | N7: =H7*Assumptions!$C$9 -> 34.982445 | O7: =I7*Assumptions!$C$9 -> 2.2881599 | P7: =J7*Assumptions!$C$9 -> 2.2331561 | Q7: https://data.openei.org/files/6006/2024_v4_Workbook_7-22-2026.xlsx
A8: CT F-frame | B8: NG Combustion Turbine (F-Frame) | C8: Advanced | D8: 30 | E8: 1270.476 | F8: 1221.4444 | G8: 25 | H8: 24.2 | I8: 6.94 | J8: 6.94 | K8: =E8*Assumptions!$C$9 -> 1397.6213 | L8: =F8*Assumptions!$C$9 -> 1343.6827 | M8: =G8*Assumptions!$C$9 -> 27.501922 | N8: =H8*Assumptions!$C$9 -> 26.621861 | O8: =I8*Assumptions!$C$9 -> 7.6345336 | P8: =J8*Assumptions!$C$9 -> 7.6345336 | Q8: https://data.openei.org/files/6006/2024_v4_Workbook_7-22-2026.xlsx
A9: CT F-frame | B9: NG Combustion Turbine (F-Frame) | C9: Moderate | D9: 30 | E9: 1270.476 | F9: 1221.4444 | G9: 25 | H9: 24.2 | I9: 6.94 | J9: 6.94 | K9: =E9*Assumptions!$C$9 -> 1397.6213 | L9: =F9*Assumptions!$C$9 -> 1343.6827 | M9: =G9*Assumptions!$C$9 -> 27.501922 | N9: =H9*Assumptions!$C$9 -> 26.621861 | O9: =I9*Assumptions!$C$9 -> 7.6345336 | P9: =J9*Assumptions!$C$9 -> 7.6345336 | Q9: https://data.openei.org/files/6006/2024_v4_Workbook_7-22-2026.xlsx
A10: CT F-frame | B10: NG Combustion Turbine (F-Frame) | C10: Conservative | D10: 30 | E10: 1270.476 | F10: 1221.4444 | G10: 25 | H10: 24.2 | I10: 6.94 | J10: 6.94 | K10: =E10*Assumptions!$C$9 -> 1397.6213 | L10: =F10*Assumptions!$C$9 -> 1343.6827 | M10: =G10*Assumptions!$C$9 -> 27.501922 | N10: =H10*Assumptions!$C$9 -> 26.621861 | O10: =I10*Assumptions!$C$9 -> 7.6345336 | P10: =J10*Assumptions!$C$9 -> 7.6345336 | Q10: https://data.openei.org/files/6006/2024_v4_Workbook_7-22-2026.xlsx
A11: SMR | B11: Nuclear - Small | C11: Advanced | D11: 30 | E11: 6416.7403 | F11: 3838.5857 | G11: 118 | H11: 118 | I11: 2.2 | J11: 2.2 | K11: =E11*Assumptions!$C$9 -> 7058.9076 | L11: =F11*Assumptions!$C$9 -> 4222.7394 | M11: =G11*Assumptions!$C$9 -> 129.80907 | N11: =H11*Assumptions!$C$9 -> 129.80907 | O11: =I11*Assumptions!$C$9 -> 2.4201691 | P11: =J11*Assumptions!$C$9 -> 2.4201691 | Q11: https://data.openei.org/files/6006/2024_v4_Workbook_7-22-2026.xlsx
A12: SMR | B12: Nuclear - Small | C12: Moderate | D12: 30 | E12: 9650.0007 | F12: 7862.9635 | G12: 136 | H12: 136 | I12: 2.6 | J12: 2.6 | K12: =E12*Assumptions!$C$9 -> 10615.743 | L12: =F12*Assumptions!$C$9 -> 8649.8644 | M12: =G12*Assumptions!$C$9 -> 149.61046 | N12: =H12*Assumptions!$C$9 -> 149.61046 | O12: =I12*Assumptions!$C$9 -> 2.8601999 | P12: =J12*Assumptions!$C$9 -> 2.8601999 | Q12: https://data.openei.org/files/6006/2024_v4_Workbook_7-22-2026.xlsx
A13: SMR | B13: Nuclear - Small | C13: Conservative | D13: 30 | E13: 12681.127 | F13: 12053.348 | G13: 216 | H13: 216 | I13: 2.8 | J13: 2.8 | K13: =E13*Assumptions!$C$9 -> 13950.214 | L13: =F13*Assumptions!$C$9 -> 13259.61 | M13: =G13*Assumptions!$C$9 -> 237.61661 | N13: =H13*Assumptions!$C$9 -> 237.61661 | O13: =I13*Assumptions!$C$9 -> 3.0802153 | P13: =J13*Assumptions!$C$9 -> 3.0802153 | Q13: https://data.openei.org/files/6006/2024_v4_Workbook_7-22-2026.xlsx
A14: Wind class 1 | B14: Land-Based Wind - Class 1 - Technology 1 | C14: Advanced | D14: 30 | E14: 1341.6723 | F14: 1258.7993 | G14: 26.314454 | H14: 23.834381 | I14: 0 | J14: 0 | K14: =E14*Assumptions!$C$9 -> 1475.9427 | L14: =F14*Assumptions!$C$9 -> 1384.776 | M14: =G14*Assumptions!$C$9 -> 28.947922 | N14: =H14*Assumptions!$C$9 -> 26.219652 | O14: =I14*Assumptions!$C$9 -> 0 | P14: =J14*Assumptions!$C$9 -> 0 | Q14: https://data.openei.org/files/6006/2024_v4_Workbook_7-22-2026.xlsx
A15: Wind class 1 | B15: Land-Based Wind - Class 1 - Technology 1 | C15: Moderate | D15: 30 | E15: 1407.9532 | F15: 1334.692 | G15: 29.263773 | H15: 28.261218 | I15: 0 | J15: 0 | K15: =E15*Assumptions!$C$9 -> 1548.8568 | L15: =F15*Assumptions!$C$9 -> 1468.2638 | M15: =G15*Assumptions!$C$9 -> 32.1924 | N15: =H15*Assumptions!$C$9 -> 31.089513 | O15: =I15*Assumptions!$C$9 -> 0 | P15: =J15*Assumptions!$C$9 -> 0 | Q15: https://data.openei.org/files/6006/2024_v4_Workbook_7-22-2026.xlsx
A16: Wind class 1 | B16: Land-Based Wind - Class 1 - Technology 1 | C16: Conservative | D16: 30 | E16: 1577.3918 | F16: 1522.1515 | G16: 30.910899 | H16: 30.290881 | I16: 0 | J16: 0 | K16: =E16*Assumptions!$C$9 -> 1735.2522 | L16: =F16*Assumptions!$C$9 -> 1674.4837 | M16: =G16*Assumptions!$C$9 -> 34.004365 | N16: =H16*Assumptions!$C$9 -> 33.322298 | O16: =I16*Assumptions!$C$9 -> 0 | P16: =J16*Assumptions!$C$9 -> 0 | Q16: https://data.openei.org/files/6006/2024_v4_Workbook_7-22-2026.xlsx
... A22: Solar PV | B22: Utility PV - Class 1 | C22: Conservative | D22: 30 | E22: 1364.9377 | F22: 1189.2471 | G22: 19.724805 | H22: 17.961888 | I22: 0 | J22: 0 | K22: =E22*Assumptions!$C$9 -> 1501.5365 | L22: =F22*Assumptions!$C$9 -> 1308.2632 | M22: =G22*Assumptions!$C$9 -> 21.698802 | N22: =H22*Assumptions!$C$9 -> 19.759458 | O22: =I22*Assumptions!$C$9 -> 0 | P22: =J22*Assumptions!$C$9 -> 0 | Q22: https://data.openei.org/files/6006/2024_v4_Workbook_7-22-2026.xlsx
A23: BESS 2h | B23: Utility-Scale Battery Storage - 2Hr | C23: Advanced | D23: * | E23: 706.0799 | F23: 652.792 | G23: 14.529716 | H23: 13.244482 | I23: 0 | J23: 0 | K23: =E23*Assumptions!$C$9 -> 776.74218 | L23: =F23*Assumptions!$C$9 -> 718.12139 | M23: =G23*Assumptions!$C$9 -> 15.983805 | N23: =H23*Assumptions!$C$9 -> 14.569948 | O23: =I23*Assumptions!$C$9 -> 0 | P23: =J23*Assumptions!$C$9 -> 0 | Q23: https://data.openei.org/files/6006/2024_v4_Workbook_7-22-2026.xlsx
A24: BESS 2h | B24: Utility-Scale Battery Storage - 2Hr | C24: Moderate | D24: * | E24: 941.9756 | F24: 884.34444 | G24: 20.219209 | H24: 18.829221 | I24: 0 | J24: 0 | K24: =E24*Assumptions!$C$9 -> 1036.2456 | L24: =F24*Assumptions!$C$9 -> 972.84687 | M24: =G24*Assumptions!$C$9 -> 22.242684 | N24: =H24*Assumptions!$C$9 -> 20.713591 | O24: =I24*Assumptions!$C$9 -> 0 | P24: =J24*Assumptions!$C$9 -> 0 | Q24: https://data.openei.org/files/6006/2024_v4_Workbook_7-22-2026.xlsx
A25: BESS 2h | B25: Utility-Scale Battery Storage - 2Hr | C25: Conservative | D25: * | E25: 1114.4629 | F25: 1079.859 | G25: 24.379376 | H25: 23.544775 | I25: 0 | J25: 0 | K25: =E25*Assumptions!$C$9 -> 1225.9949 | L25: =F25*Assumptions!$C$9 -> 1187.9279 | M25: =G25*Assumptions!$C$9 -> 26.819188 | N25: =H25*Assumptions!$C$9 -> 25.901062 | O25: =I25*Assumptions!$C$9 -> 0 | P25: =J25*Assumptions!$C$9 -> 0 | Q25: https://data.openei.org/files/6006/2024_v4_Workbook_7-22-2026.xlsx
A26: BESS 4h | B26: Utility-Scale Battery Storage - 4Hr | C26: Advanced | D26: * | E26: 1117.5994 | F26: 1028.7117 | G26: 24.455023 | H26: 22.311171 | I26: 0 | J26: 0 | K26: =E26*Assumptions!$C$9 -> 1229.4452 | L26: =F26*Assumptions!$C$9 -> 1131.662 | M26: =G26*Assumptions!$C$9 -> 26.902405 | N26: =H26*Assumptions!$C$9 -> 24.544003 | O26: =I26*Assumptions!$C$9 -> 0 | P26: =J26*Assumptions!$C$9 -> 0 | Q26: https://data.openei.org/files/6006/2024_v4_Workbook_7-22-2026.xlsx
A27: BESS 4h | B27: Utility-Scale Battery Storage - 4Hr | C27: Moderate | D27: * | E27: 1451.3156 | F27: 1347.3964 | G27: 32.503818 | H27: 29.997424 | I27: 0 | J27: 0 | K27: =E27*Assumptions!$C$9 -> 1596.5588 | L27: =F27*Assumptions!$C$9 -> 1482.2396 | M27: =G27*Assumptions!$C$9 -> 35.756699 | N27: =H27*Assumptions!$C$9 -> 32.999473 | O27: =I27*Assumptions!$C$9 -> 0 | P27: =J27*Assumptions!$C$9 -> 0 | Q27: https://data.openei.org/files/6006/2024_v4_Workbook_7-22-2026.xlsx
A28: BESS 4h | B28: Utility-Scale Battery Storage - 4Hr | C28: Conservative | D28: * | E28: 1774.9148 | F28: 1717.701 | G28: 40.308604 | H28: 38.928683 | I28: 0 | J28: 0 | K28: =E28*Assumptions!$C$9 -> 1952.5427 | L28: =F28*Assumptions!$C$9 -> 1889.6032 | M28: =G28*Assumptions!$C$9 -> 44.342563 | N28: =H28*Assumptions!$C$9 -> 42.824544 | O28: =I28*Assumptions!$C$9 -> 0 | P28: =J28*Assumptions!$C$9 -> 0 | Q28: https://data.openei.org/files/6006/2024_v4_Workbook_7-22-2026.xlsx
A29: BESS 6h | B29: Utility-Scale Battery Storage - 6Hr | C29: Advanced | D29: * | E29: 1529.1188 | F29: 1404.6315 | G29: 34.380329 | H29: 31.377859 | I29: 0 | J29: 0 | K29: =E29*Assumptions!$C$9 -> 1682.1483 | L29: =F29*Assumptions!$C$9 -> 1545.2026 | M29: =G29*Assumptions!$C$9 -> 37.821005 | N29: =H29*Assumptions!$C$9 -> 34.518057 | O29: =I29*Assumptions!$C$9 -> 0 | P29: =J29*Assumptions!$C$9 -> 0 | Q29: https://data.openei.org/files/6006/2024_v4_Workbook_7-22-2026.xlsx
A30: BESS 6h | B30: Utility-Scale Battery Storage - 6Hr | C30: Moderate | D30: * | E30: 1960.6556 | F30: 1810.4484 | G30: 44.788428 | H30: 41.165627 | I30: 0 | J30: 0 | K30: =E30*Assumptions!$C$9 -> 2156.8719 | L30: =F30*Assumptions!$C$9 -> 1991.6324 | M30: =G30*Assumptions!$C$9 -> 49.270714 | N30: =H30*Assumptions!$C$9 -> 45.285354 | O30: =I30*Assumptions!$C$9 -> 0 | P30: =J30*Assumptions!$C$9 -> 0 | Q30: https://data.openei.org/files/6006/2024_v4_Workbook_7-22-2026.xlsx
A31: BESS 6h | B31: Utility-Scale Battery Storage - 6Hr | C31: Conservative | D31: * | E31: 2435.3667 | F31: 2355.543 | G31: 56.237832 | H31: 54.312591 | I31: 0 | J31: 0 | K31: =E31*Assumptions!$C$9 -> 2679.0906 | L31: =F31*Assumptions!$C$9 -> 2591.2784 | M31: =G31*Assumptions!$C$9 -> 61.865939 | N31: =H31*Assumptions!$C$9 -> 59.748026 | O31: =I31*Assumptions!$C$9 -> 0 | P31: =J31*Assumptions!$C$9 -> 0 | Q31: https://data.openei.org/files/6006/2024_v4_Workbook_7-22-2026.xlsx
A34: Notes
A35: ATB 2024b monetary values are in 2022 dollars.
A36: The December 2025 2024b reference refresh did not change the underlying ATB data.
A37: Wind Classes 1 and 7 are both retained because the resource/site class choice can affect CAPEX and is relevant for ERCOT.

Sheet NLR_BESS_2025
A1: NLR 2025 Utility-Scale Battery Cost Projection — 4-hour Li-ion
A2: Source: | B2: https://www.nlr.gov/docs/fy25osti/93281.pdf
A4: Year | B4: Low (2024$/kWh) | C4: Mid (2024$/kWh) | D4: High (2024$/kWh) | E4: Low 4h (2024$/kW) | F4: Mid 4h (2024$/kW) | G4: High 4h (2024$/kW) | H4: Low 4h (2025$/kW) | I4: Mid 4h (2025$/kW) | J4: High 4h (2025$/kW) | K4: Source URL
A5: 2024 | B5: 334 | C5: 334 | D5: 334 | E5: =B5*4 -> 1336 | F5: =C5*4 -> 1336 | G5: =D5*4 -> 1336 | H5: =E5*Assumptions!$C$11 -> 1371.1537 | I5: =F5*Assumptions!$C$11 -> 1371.1537 | J5: =G5*Assumptions!$C$11 -> 1371.1537 | K5: https://www.nlr.gov/docs/fy25osti/93281.pdf
A6: 2025 | B6: 295 | C6: 321 | D6: 350 | E6: =B6*4 -> 1180 | F6: =C6*4 -> 1284 | G6: =D6*4 -> 1400 | H6: =E6*Assumptions!$C$11 -> 1211.049 | I6: =F6*Assumptions!$C$11 -> 1317.7855 | J6: =G6*Assumptions!$C$11 -> 1436.8378 | K6: https://www.nlr.gov/docs/fy25osti/93281.pdf
A7: 2026 | B7: 255 | C7: 308 | D7: 366 | E7: =B7*4 -> 1020 | F7: =C7*4 -> 1232 | G7: =D7*4 -> 1464 | H7: =E7*Assumptions!$C$11 -> 1046.8389 | I7: =F7*Assumptions!$C$11 -> 1264.4172 | J7: =G7*Assumptions!$C$11 -> 1502.5218 | K7: https://www.nlr.gov/docs/fy25osti/93281.pdf
A8: 2027 | B8: 243 | C8: 301 | D8: 363 | E8: =B8*4 -> 972 | F8: =C8*4 -> 1204 | G8: =D8*4 -> 1452 | H8: =E8*Assumptions!$C$11 -> 997.57593 | I8: =F8*Assumptions!$C$11 -> 1235.6805 | J8: =G8*Assumptions!$C$11 -> 1490.206 | K8: https://www.nlr.gov/docs/fy25osti/93281.pdf
A9: 2028 | B9: 231 | C9: 293 | D9: 360 | E9: =B9*4 -> 924 | F9: =C9*4 -> 1172 | G9: =D9*4 -> 1440 | H9: =E9*Assumptions!$C$11 -> 948.31292 | I9: =F9*Assumptions!$C$11 -> 1202.8385 | J9: =G9*Assumptions!$C$11 -> 1477.8903 | K9: https://www.nlr.gov/docs/fy25osti/93281.pdf
A10: 2029 | B10: 219 | C10: 286 | D10: 357 | E10: =B10*4 -> 876 | F10: =C10*4 -> 1144 | G10: =D10*4 -> 1428 | H10: =E10*Assumptions!$C$11 -> 899.04991 | I10: =F10*Assumptions!$C$11 -> 1174.1017 | J10: =G10*Assumptions!$C$11 -> 1465.5745 | K10: https://www.nlr.gov/docs/fy25osti/93281.pdf
A11: 2030 | B11: 207 | C11: 279 | D11: 354 | E11: =B11*4 -> 828 | F11: =C11*4 -> 1116 | G11: =D11*4 -> 1416 | H11: =E11*Assumptions!$C$11 -> 849.7869 | I11: =F11*Assumptions!$C$11 -> 1145.365 | J11: =G11*Assumptions!$C$11 -> 1453.2588 | K11: https://www.nlr.gov/docs/fy25osti/93281.pdf
A12: 2031 | B12: 195 | C12: 272 | D12: 351 | E12: =B12*4 -> 780 | F12: =C12*4 -> 1088 | G12: =D12*4 -> 1404 | H12: =E12*Assumptions!$C$11 -> 800.52389 | I12: =F12*Assumptions!$C$11 -> 1116.6282 | J12: =G12*Assumptions!$C$11 -> 1440.943 | K12: https://www.nlr.gov/docs/fy25osti/93281.pdf
A13: 2032 | B13: 183 | C13: 265 | D13: 348 | E13: =B13*4 -> 732 | F13: =C13*4 -> 1060 | G13: =D13*4 -> 1392 | H13: =E13*Assumptions!$C$11 -> 751.26089 | I13: =F13*Assumptions!$C$11 -> 1087.8914 | J13: =G13*Assumptions!$C$11 -> 1428.6273 | K13: https://www.nlr.gov/docs/fy25osti/93281.pdf
A14: 2033 | B14: 171 | C14: 257 | D14: 345 | E14: =B14*4 -> 684 | F14: =C14*4 -> 1028 | G14: =D14*4 -> 1380 | H14: =E14*Assumptions!$C$11 -> 701.99788 | I14: =F14*Assumptions!$C$11 -> 1055.0494 | J14: =G14*Assumptions!$C$11 -> 1416.3115 | K14: https://www.nlr.gov/docs/fy25osti/93281.pdf
A15: 2034 | B15: 159 | C15: 250 | D15: 342 | E15: =B15*4 -> 636 | F15: =C15*4 -> 1000 | G15: =D15*4 -> 1368 | H15: =E15*Assumptions!$C$11 -> 652.73487 | I15: =F15*Assumptions!$C$11 -> 1026.3127 | J15: =G15*Assumptions!$C$11 -> 1403.9958 | K15: https://www.nlr.gov/docs/fy25osti/93281.pdf
A16: 2035 | B16: 147 | C16: 243 | D16: 339 | E16: =B16*4 -> 588 | F16: =C16*4 -> 972 | G16: =D16*4 -> 1356 | H16: =E16*Assumptions!$C$11 -> 603.47186 | I16: =F16*Assumptions!$C$11 -> 997.57593 | J16: =G16*Assumptions!$C$11 -> 1391.68 | K16: https://www.nlr.gov/docs/fy25osti/93281.pdf
... A21: 2040 | B21: 134 | C21: 221 | D21: 329 | E21: =B21*4 -> 536 | F21: =C21*4 -> 884 | G21: =D21*4 -> 1316 | H21: =E21*Assumptions!$C$11 -> 550.1036 | I21: =F21*Assumptions!$C$11 -> 907.26041 | J21: =G21*Assumptions!$C$11 -> 1350.6275 | K21: https://www.nlr.gov/docs/fy25osti/93281.pdf
A24: Notes
A25: The report states that $/kWh can be converted to $/kW by multiplying by storage duration; this sheet uses four hours.
A26: Use this newer series as a battery-specific sensitivity to the older ATB trajectory.

Sheet LBNL_Actuals
A1: Berkeley Lab — Empirical Installed-Cost Benchmarks (Calibration Only)
A4: Technology | B4: Region | C4: Project/COD year(s) | D4: Raw installed cost | E4: Raw unit / dollar year | F4: 2025$/kW equivalent | G4: Use in ERCOT CEM | H4: Notes | I4: Source URL
A5: Land-based wind | B5: ERCOT | C5: 2022–2023 | D5: 1370 | E5: 2023$/kW | F5: =D5*Assumptions!$C$10 -> 1447.5189 | G5: Strong empirical ERCOT calibration | H5: Capacity-weighted regional mean; historical, not a forward forecast | I5: https://emp.lbl.gov/sites/default/files/2024-08/Land-Based%20Wind%20Market%20Report_2024%20Edition.pdf
A6: Utility-scale solar PV | B6: U.S. | C6: 2024 | D6: 1610 | E6: 2024$/kW-AC | F6: =D6*Assumptions!$C$11 -> 1652.3634 | G6: National empirical calibration | H6: Capacity-weighted mean; preliminary 2024 sample; not ERCOT-specific | I6: https://emp.lbl.gov/publications/us-utility-scale-solar-2025-data
A8: Important
A9: These are observed installed-cost benchmarks. Do not treat them as 2030/2035 projections.
A10: The ERCOT wind value is especially useful for diagnosing whether a future wind CAPEX path is too conservative.

Sheet Compare_2030_2035
A1: Harmonized CAPEX Comparison — All Values in Real 2025$/kW
A4: Technology | B4: ERCOT LTSA 2030 | C4: ATB Moderate 2030 | D4: ATB Advanced 2030 | E4: ATB Conservative 2030 | F4: EIA TRE current anchor | G4: NLR BESS Mid 2030 | H4: LBNL empirical anchor | I4: ERCOT LTSA 2035 | J4: ATB Moderate 2035 | K4: ATB Advanced 2035 | L4: ATB Conservative 2035 | M4: NLR BESS Mid 2035 | N4: Interpretation | O4: Recommended Base 2030 | P4: Recommended Base 2035 | Q4: Recommended Base Source
A5: CC multi-shaft | B5: =ERCOT_LTSA_2026!B30 -> 1314.8599 | C5: =NLR_ATB_2024b!K6 -> 1543.7457 | D5: =NLR_ATB_2024b!K5 -> 1519.3508 | E5: =NLR_ATB_2024b!K7 -> 1568.1406 | F5: =EIA_AEO2026_TRE!G6 -> 930 | I5: =ERCOT_LTSA_2026!B35 -> 1254.1144 | J5: =NLR_ATB_2024b!L6 -> 1477.7936 | K5: =NLR_ATB_2024b!L5 -> 1438.0752 | L5: =NLR_ATB_2024b!L7 -> 1517.3894 | N5: Recommended base = ERCOT LTSA; EIA is a lower current regional anchor. | O5: =Recommended_CEM_Base!D4 -> 1314.8599 | P5: =Recommended_CEM_Base!K4 -> 1254.1144 | Q5: =Recommended_CEM_Base!O4 -> ERCOT 2026 LTSA
A6: Advanced CT | B6: =ERCOT_LTSA_2026!C30 -> 1193.778 | C6: =NLR_ATB_2024b!K9 -> 1397.6213 | D6: =NLR_ATB_2024b!K8 -> 1397.6213 | E6: =NLR_ATB_2024b!K10 -> 1397.6213 | F6: =EIA_AEO2026_TRE!G9 -> 1033 | I6: =ERCOT_LTSA_2026!C35 -> 1109.3161 | J6: =NLR_ATB_2024b!L9 -> 1343.6827 | K6: =NLR_ATB_2024b!L8 -> 1343.6827 | L6: =NLR_ATB_2024b!L10 -> 1343.6827 | N6: Recommended base = ERCOT LTSA; compare with EIA industrial-frame CT. | O6: =Recommended_CEM_Base!D5 -> 1193.778 | P6: =Recommended_CEM_Base!K5 -> 1109.3161 | Q6: =Recommended_CEM_Base!O5 -> ERCOT 2026 LTSA
A7: SMR | B7: =ERCOT_LTSA_2026!E30 -> 8608.4759 | C7: =NLR_ATB_2024b!K12 -> 10615.743 | D7: =NLR_ATB_2024b!K11 -> 7058.9076 | E7: =NLR_ATB_2024b!K13 -> 13950.214 | F7: =EIA_AEO2026_TRE!G11 -> 9366 | I7: =ERCOT_LTSA_2026!E35 -> 8133.6439 | J7: =NLR_ATB_2024b!L12 -> 8649.8644 | K7: =NLR_ATB_2024b!L11 -> 4222.7394 | L7: =NLR_ATB_2024b!L13 -> 13259.61 | N7: Recommended central = ERCOT LTSA; retain wide ATB low/high sensitivity. | O7: =Recommended_CEM_Base!D7 -> 8608.4759 | P7: =Recommended_CEM_Base!K7 -> 8133.6439 | Q7: =Recommended_CEM_Base!O7 -> ERCOT 2026 LTSA
A8: Wind | B8: =ERCOT_LTSA_2026!F30 -> 2010.8567 | C8: =NLR_ATB_2024b!K15 -> 1548.8568 | D8: =NLR_ATB_2024b!K14 -> 1475.9427 | E8: =NLR_ATB_2024b!K16 -> 1735.2522 | F8: =EIA_AEO2026_TRE!G13 -> 1562 | H8: =LBNL_Actuals!F5 -> 1447.5189 | I8: =ERCOT_LTSA_2026!F35 -> 1960.4085 | J8: =NLR_ATB_2024b!L15 -> 1468.2638 | K8: =NLR_ATB_2024b!L14 -> 1384.776 | L8: =NLR_ATB_2024b!L16 -> 1674.4837 | N8: Recommended base = ATB Moderate Class 1; ERCOT LTSA = conservative/high planning benchmark. | O8: =Recommended_CEM_Base!D8 -> 1548.8568 | P8: =Recommended_CEM_Base!K8 -> 1468.2638 | Q8: =Recommended_CEM_Base!O8 -> NLR/NREL ATB 2024b Moderate — Wind Class 1
A9: Solar | B9: =ERCOT_LTSA_2026!G30 -> 1171.3554 | C9: =NLR_ATB_2024b!K21 -> 1312.9208 | D9: =NLR_ATB_2024b!K20 -> 1176.6054 | E9: =NLR_ATB_2024b!K22 -> 1501.5365 | F9: =EIA_AEO2026_TRE!G14 -> 1342 | H9: =LBNL_Actuals!F6 -> 1652.3634 | I9: =ERCOT_LTSA_2026!G35 -> 1052.2012 | J9: =NLR_ATB_2024b!L21 -> 984.92209 | K9: =NLR_ATB_2024b!L20 -> 751.23849 | L9: =NLR_ATB_2024b!L22 -> 1308.2632 | N9: Recommended base = ERCOT LTSA; source disagreement is comparatively modest. | O9: =Recommended_CEM_Base!D9 -> 1171.3554 | P9: =Recommended_CEM_Base!K9 -> 1052.2012 | Q9: =Recommended_CEM_Base!O9 -> ERCOT 2026 LTSA
A10: BESS 2h | B10: =ERCOT_LTSA_2026!H30 -> 697.79061 | C10: =NLR_ATB_2024b!K24 -> 1036.2456 | D10: =NLR_ATB_2024b!K23 -> 776.74218 | E10: =NLR_ATB_2024b!K25 -> 1225.9949 | I10: =ERCOT_LTSA_2026!H35 -> 645.15699 | J10: =NLR_ATB_2024b!L24 -> 972.84687 | K10: =NLR_ATB_2024b!L23 -> 718.12139 | L10: =NLR_ATB_2024b!L25 -> 1187.9279 | N10: Recommended base = ERCOT LTSA; alternate duration, while 4h remains the preferred core storage case. | O10: =Recommended_CEM_Base!D10 -> 697.79061 | P10: =Recommended_CEM_Base!K10 -> 645.15699 | Q10: =Recommended_CEM_Base!O10 -> ERCOT 2026 LTSA
A11: BESS 4h | B11: =ERCOT_LTSA_2026!I30 -> 1200.9532 | C11: =NLR_ATB_2024b!K27 -> 1596.5588 | D11: =NLR_ATB_2024b!K26 -> 1229.4452 | E11: =NLR_ATB_2024b!K28 -> 1952.5427 | F11: =EIA_AEO2026_TRE!G12 -> 1500 | G11: =NLR_BESS_2025!I11 -> 1145.365 | I11: =ERCOT_LTSA_2026!I35 -> 1110.9249 | J11: =NLR_ATB_2024b!L27 -> 1482.2396 | K11: =NLR_ATB_2024b!L26 -> 1131.662 | L11: =NLR_ATB_2024b!L28 -> 1889.6032 | M11: =NLR_BESS_2025!I16 -> 997.57593 | N11: Recommended base = NLR 2025 Mid; use NLR Low/High as the primary battery sensitivities. | O11: =Recommended_CEM_Base!D11 -> 1145.365 | P11: =Recommended_CEM_Base!K11 -> 997.57593 | Q11: =Recommended_CEM_Base!O11 -> NLR 2025 Utility-Scale Battery Storage — Mid
A12: BESS 6h | B12: =ERCOT_LTSA_2026!J30 -> 1705.0128 | C12: =NLR_ATB_2024b!K30 -> 2156.8719 | D12: =NLR_ATB_2024b!K29 -> 1682.1483 | E12: =NLR_ATB_2024b!K31 -> 2679.0906 | I12: =ERCOT_LTSA_2026!J35 -> 1576.6929 | J12: =NLR_ATB_2024b!L30 -> 1991.6324 | K12: =NLR_ATB_2024b!L29 -> 1545.2026 | L12: =NLR_ATB_2024b!L31 -> 2591.2784 | N12: Recommended base = ERCOT LTSA; alternate duration, while 4h remains the preferred core storage case. | O12: =Recommended_CEM_Base!D12 -> 1705.0128 | P12: =Recommended_CEM_Base!K12 -> 1576.6929 | Q12: =Recommended_CEM_Base!O12 -> ERCOT 2026 LTSA
A13: Diesel backup generator | N13: Standby/resilience generator; lower CAPEX but not intended as the utility-scale peaker representation. | O13: =Recommended_CEM_Base!D13 -> 800 | P13: =Recommended_CEM_Base!K13 -> 800 | Q13: Backup-generator synthesis (NREL / EDF / BofA / MIT)
A14: Diesel peaker plant | N14: Grid-connected peaker; EIA Texas engineering benchmark used as central CAPEX with current petroleum-liquid construction costs as a lower empirical check. | O14: =Recommended_CEM_Base!D15 -> 1373.8713 | P14: =Recommended_CEM_Base!K15 -> 1373.8713 | Q14: EIA/S&L Texas 20-MW ICE engineering benchmark
A16: How to read this table
A17: The recommended base is technology-specific; see columns O:Q and Recommended_CEM_Base. ERCOT LTSA is not treated as the central source for every technology.
A18: EIA TRE is a current regional anchor, not an explicit 2030/2035 forecast. LBNL is an empirical historical calibration.
A19: Diesel backup and diesel peaker are intentionally separate because their installed-system scope and use case differ materially.

Sheet CEM_BaseCase
A1: ERCOT LTSA Benchmark + External Diesel Assumptions — 2030 / 2035 (Real 2025$)
A2: Benchmark tab: ERCOT LTSA CAPEX is used for technologies covered by LTSA. Diesel is shown separately as (1) backup generator and (2) utility-scale peaker because LTSA does not provide diesel-specific series.
A3: Technology | B3: Economic life (yr) | C3: Real WACC | D3: 2030 CAPEX (2025$/kW) | E3: CRF | F3: 2030 annualized CAPEX (2025$/kW-yr) | G3: 2030 FOM (2025$/kW-yr) | H3: 2030 total fixed (2025$/kW-yr) | I3: VOM (2025$/MWh) | J3: Heat rate (Btu/kWh) | K3: 2035 CAPEX (2025$/kW) | L3: 2035 annualized CAPEX (2025$/kW-yr) | M3: 2035 FOM (2025$/kW-yr) | N3: 2035 total fixed (2025$/kW-yr) | O3: CAPEX source | P3: O&M source | Q3: Modeling note
A4: CC multi-shaft | B4: =Assumptions!B15 -> 30 | C4: =Assumptions!$B$5 -> 0.07 | D4: =ERCOT_LTSA_2026!B30 -> 1314.8599 | E4: =C4*(1+C4)^B4/((1+C4)^B4-1) -> 0.080586404 | F4: =D4*E4 -> 105.95983 | G4: =EIA_AEO2026_TRE!H6 -> 12.69 | H4: =F4+IF(G4="",0,G4) -> 118.64983 | I4: =EIA_AEO2026_TRE!I6 -> 3.57 | J4: =EIA_AEO2026_TRE!J6 -> 6226 | K4: =ERCOT_LTSA_2026!B35 -> 1254.1144 | L4: =K4*E4 -> 101.06457 | M4: =EIA_AEO2026_TRE!H6 -> 12.69 | N4: =L4+IF(M4="",0,M4) -> 113.75457 | O4: ERCOT 2026 LTSA | P4: EIA AEO2026; held constant in real 2025$ unless changed | Q4: Base CAPEX = ERCOT LTSA; O&M/performance = EIA multi-shaft CC.
A5: Advanced CT | B5: =Assumptions!B16 -> 30 | C5: =Assumptions!$B$5 -> 0.07 | D5: =ERCOT_LTSA_2026!C30 -> 1193.778 | E5: =C5*(1+C5)^B5/((1+C5)^B5-1) -> 0.080586404 | F5: =D5*E5 -> 96.202277 | G5: =EIA_AEO2026_TRE!H9 -> 7.18 | H5: =F5+IF(G5="",0,G5) -> 103.38228 | I5: =EIA_AEO2026_TRE!I9 -> 4.17 | J5: =EIA_AEO2026_TRE!J9 -> 9142 | K5: =ERCOT_LTSA_2026!C35 -> 1109.3161 | L5: =K5*E5 -> 89.395793 | M5: =EIA_AEO2026_TRE!H9 -> 7.18 | N5: =L5+IF(M5="",0,M5) -> 96.575793 | O5: ERCOT 2026 LTSA | P5: EIA AEO2026; held constant in real 2025$ unless changed | Q5: Base CAPEX = ERCOT LTSA; O&M/performance = EIA industrial-frame CT.
A6: ICE | B6: =Assumptions!B17 -> 30 | C6: =Assumptions!$B$5 -> 0.07 | D6: =ERCOT_LTSA_2026!D30 -> 2102.3408 | E6: =C6*(1+C6)^B6/((1+C6)^B6-1) -> 0.080586404 | F6: =D6*E6 -> 169.42009 | H6: =F6+IF(G6="",0,G6) -> 169.42009 | K6: =ERCOT_LTSA_2026!D35 -> 2036.8298 | L6: =K6*E6 -> 164.14079 | N6: =L6+IF(M6="",0,M6) -> 164.14079 | O6: ERCOT 2026 LTSA | P6: Not populated — add engine-specific O&M/performance source | Q6: ERCOT CAPEX is available, but O&M/heat rate should come from the engine technology selected in the model.
A7: SMR | B7: =Assumptions!B18 -> 60 | C7: =Assumptions!$B$5 -> 0.07 | D7: =ERCOT_LTSA_2026!E30 -> 8608.4759 | E7: =C7*(1+C7)^B7/((1+C7)^B7-1) -> 0.071229226 | F7: =D7*E7 -> 613.17507 | G7: =EIA_AEO2026_TRE!H11 -> 127.62 | H7: =F7+IF(G7="",0,G7) -> 740.79507 | I7: =EIA_AEO2026_TRE!I11 -> 3.32 | J7: =EIA_AEO2026_TRE!J11 -> 10445 | K7: =ERCOT_LTSA_2026!E35 -> 8133.6439 | L7: =K7*E7 -> 579.35315 | M7: =EIA_AEO2026_TRE!H11 -> 127.62 | N7: =L7+IF(M7="",0,M7) -> 706.97315 | O7: ERCOT 2026 LTSA | P7: EIA AEO2026; held constant in real 2025$ unless changed | Q7: Large uncertainty; retain ATB Advanced/Moderate/Conservative sensitivities.
